Workbook

Sheet Salary
Q1: 31
Q2: Salary for the month of December 2025
F3: Monthly CTC for Employees | Q3: Gross Earnings | Y3: Deduction
A4: EMP CODE | B4: S.No. | C4: NAME OF EMPLOYEE | D4: DOJ | E4: Entity | F4: BASIC+DA | G4: HRA | H4: Conveyance | I4: Statutory Bonus | J4: Special Allowance | K4: Gross | L4: Employer PF | M4: Employer ESIC | N4: CTC | O4: Reimbursement Quarterly | P4: Gross CTC | Q4: Pay Days | R4: BASIC | S4: HRA | T4: Conveyance | U4: Statutory Bonus | V4: Special Allowance | W4: Incentive /Others | X4: Total Gross | Y4: PF | Z4: ESIC | AA4: TDS / Advance | AB4: Total Deduction | AC4: Net Salary | AD4: Expenses | AE4: Salary relesaed
C5: Reinste
B6: 1 | C6: Gulab | D6: 01.06.2018 | E6: Reinste | F6: =K6/2 -> 7189.5 | G6: =ROUND(+F6*0.5,0) -> 3595 | H6: 1600 | I6: =+F6*0.09 -> 647.055 | J6: =K6-F6-G6-I6-H6 -> 1347.445 | K6: =12629+750+1000 -> 14379 | L6: =ROUND((K6-G6)*0.12,0) -> 1294 | N6: =+K6+L6+M6 -> 15673 | P6: =+O6+N6 -> 15673 | Q6: 31 | R6: =ROUND(F6/$Q$1*Q6,0) -> 7190 | S6: =ROUND(G6/$Q$1*Q6,0) -> 3595 | T6: =ROUND(H6/$Q$1*Q6,0) -> 1600 | U6: =ROUND(I6/$Q$1*Q6,0) -> 647 | V6: =ROUND(J6/$Q$1*Q6,0) -> 1347 | X6: =SUM(R6:V6) -> 14379 | Y6: =MIN(1800,IF(L6>0,ROUND((X6-S6)*0.12,0),0)) -> 1294 | Z6: =+IF(M6>0,ROUNDUP((X6)*0.0175,0),0) -> 0 | AA6: 5000 | AB6: =+SUM(Y6:AA6) -> 6294 | AC6: =+X6-AB6+W6 -> 8085 | AD6: ='Expenses '!AC6 -> 1500
B7: 2 | C7: Garima Singh | D7: 19.05.2022 | E7: Reinste | F7: =K7/2 -> 20000 | G7: =ROUND(+F7*0.5,0) -> 10000 | H7: 1601 | I7: =+F7*0.09 -> 1800 | J7: =K7-F7-G7-I7-H7 -> 6599 | K7: 40000 | N7: =+K7+L7+M7 -> 40000 | P7: =+O7+N7 -> 40000 | Q7: 23.5 | R7: =ROUND(F7/$Q$1*Q7,0) -> 15161 | S7: =ROUND(G7/$Q$1*Q7,0) -> 7581 | T7: =ROUND(H7/$Q$1*Q7,0) -> 1214 | U7: =ROUND(I7/$Q$1*Q7,0) -> 1365 | V7: =ROUND(J7/$Q$1*Q7,0) -> 5002 | W7: 589 | X7: =SUM(R7:V7) -> 30323 | AB7: =+SUM(Y7:AA7) -> 0 | AC7: =+X7-AB7+W7 -> 30912
B8: 3 | C8: Ayushi Jain | D8: 01-12-2025 | E8: Reinste | F8: =K8/2 -> 9000 | G8: =ROUND(+F8*0.5,0) -> 4500 | H8: 1600 | I8: =+F8*0.09 -> 810 | J8: =K8-F8-G8-I8-H8 -> 2090 | K8: 18000 | L8: =ROUND((K8-G8)*0.12,0) -> 1620 | N8: =+K8+L8+M8 -> 19620 | P8: =+O8+N8 -> 19620 | Q8: 28 | R8: =ROUND(F8/$Q$1*Q8,0) -> 8129 | S8: =ROUND(G8/$Q$1*Q8,0) -> 4065 | T8: =ROUND(H8/$Q$1*Q8,0) -> 1445 | U8: =ROUND(I8/$Q$1*Q8,0) -> 732 | V8: =ROUND(J8/$Q$1*Q8,0) -> 1888 | W8: 6000 | X8: =SUM(R8:V8) -> 16259 | Y8: =MIN(1800,IF(L8>0,ROUND((X8-S8)*0.12,0),0)) -> 1463 | Z8: =+IF(M8>0,ROUNDUP((X8)*0.0175,0),0) -> 0 | AB8: =+SUM(Y8:AA8) -> 1463 | AC8: =+X8-AB8+W8 -> 20796 | AE8: UAN-102138518060
E9: TOTAL | F9: =SUM(F6:F8) -> 36189.5 | G9: =SUM(G6:G8) -> 18095 | H9: =SUM(H6:H8) -> 4801 | I9: =SUM(I6:I8) -> 3257.055 | J9: =SUM(J6:J8) -> 10036.445 | K9: =SUM(K6:K8) -> 72379 | L9: =SUM(L6:L8) -> 2914 | M9: =SUM(M6:M7) -> 0 | N9: =SUM(N6:N8) -> 75293 | O9: =SUM(O6:O7) -> 0 | P9: =SUM(P6:P8) -> 75293 | R9: =SUM(R6:R8) -> 30480 | S9: =SUM(S6:S8) -> 15241 | T9: =SUM(T6:T8) -> 4259 | U9: =SUM(U6:U8) -> 2744 | V9: =SUM(V6:V8) -> 8237 | W9: =SUM(W6:W8) -> 6589 | X9: =SUM(X6:X8) -> 60961 | Y9: =SUM(Y6:Y8) -> 2757 | Z9: =SUM(Z6:Z7) -> 0 | AA9: =SUM(AA6:AA8) -> 5000 | AB9: =SUM(AB6:AB8) -> 7757 | AC9: =SUM(AC6:AC8) -> 59793 | AD9: =SUM(AD6:AD8) -> 1500 | AE9: =AC9+AD9 -> 61293
C10: Consortium
B11: 1 | C11: Asan Kumar | D11: 13.04.2012 | E11: Consortium | F11: =K11/2 -> 19144.5 | G11: =ROUND(+F11*0.5,0) -> 9572 | H11: 1600 | I11: =+F11*0.09 -> 1723.005 | J11: =K11-F11-G11-I11-H11 -> 6249.495 | K11: =27789+4500+2000+4000 -> 38289 | L11: 1800 | M11: =IF(K11>21000,0,ROUND(K11*0.0325,0)) -> 0 | N11: =+K11+L11+M11 -> 40089 | P11: =+O11+N11 -> 40089 | Q11: 31 | R11: =ROUND(F11/$Q$1*Q11,0) -> 19145 | S11: =ROUND(G11/$Q$1*Q11,0) -> 9572 | T11: =ROUND(H11/$Q$1*Q11,0) -> 1600 | U11: =ROUND(I11/$Q$1*Q11,0) -> 1723 | V11: =ROUND(J11/$Q$1*Q11,0) -> 6249 | X11: =SUM(R11:V11) -> 38289 | Y11: =MIN(1800,IF(L11>0,ROUND((X11-S11)*0.12,0),0)) -> 1800 | Z11: =+IF(M11>0,ROUNDUP((X11)*0.0075,0),0) -> 0 | AB11: =+SUM(Y11:AA11) -> 1800 | AC11: =+X11-AB11+W11 -> 36489 | AD11: ='Expenses '!AC9 -> 6500
B12: 2 | C12: Ashwani Kumar | D12: 23.05.2010 | E12: Consortium | F12: =K12/2 -> 11750.5 | G12: =ROUND(+F12*0.5,0) -> 5875 | H12: 1600 | I12: =+F12*0.09 -> 1057.545 | J12: =K12-F12-G12-I12-H12 -> 3217.955 | K12: =21001+2500 -> 23501 | L12: 1800 | N12: =+K12+L12+M12 -> 25301 | P12: =+O12+N12 -> 25301 | Q12: 31 | R12: =ROUND(F12/$Q$1*Q12,0) -> 11751 | S12: =ROUND(G12/$Q$1*Q12,0) -> 5875 | T12: =ROUND(H12/$Q$1*Q12,0) -> 1600 | U12: =ROUND(I12/$Q$1*Q12,0) -> 1058 | V12: =ROUND(J12/$Q$1*Q12,0) -> 3218 | X12: =SUM(R12:V12) -> 23502 | Y12: =MIN(1800,IF(L12>0,ROUND((X12-S12)*0.12,0),0)) -> 1800 | Z12: =+IF(M12>0,ROUNDUP((X12)*0.0075,0),0) -> 0 | AA12: 2000 | AB12: =+SUM(Y12:AA12) -> 3800 | AC12: =+X12-AB12+W12 -> 19702 | AD12: ='Expenses '!AC10 -> 3000
B13: 3 | C13: Quaisher Hossain | D13: 14.03.2016 | E13: Consortium | F13: =K13/2 -> 28196 | G13: =ROUND(+F13*0.5,0) -> 14098 | H13: 1600 | I13: =+F13*0.09 -> 2537.64 | J13: =K13-F13-G13-I13-H13 -> 9960.36 | K13: =51812+4900-320 -> 56392 | L13: =AF13 -> 0 | M13: =IF(K13>21000,0,ROUND(K13*0.0325,0)) -> 0 | N13: =+K13+L13+M13 -> 56392 | P13: =+O13+N13 -> 56392 | Q13: 31 | R13: =ROUND(F13/$Q$1*Q13,0) -> 28196 | S13: =ROUND(G13/$Q$1*Q13,0) -> 14098 | T13: =ROUND(H13/$Q$1*Q13,0) -> 1600 | U13: =ROUND(I13/$Q$1*Q13,0) -> 2538 | V13: =ROUND(J13/$Q$1*Q13,0) -> 9960 | X13: =SUM(R13:V13) -> 56392 | Y13: =ROUND(((X13-S13)*12%),) -> 5075 | Z13: =+IF(M13>0,ROUNDUP((X13)*0.0075,0),0) -> 0 | AB13: =+SUM(Y13:AA13) -> 5075 | AC13: =+X13-AB13+W13 -> 51317 | AD13: ='Expenses '!AC11 -> 6000
B14: 4 | C14: Gagan Kumar | D14: 01.01.2021 | E14: Consortium | F14: =K14/2 -> 12178 | G14: =ROUND(+F14*0.5,0) -> 6089 | H14: 1600 | I14: =+F14*0.09 -> 1096.02 | J14: =K14-F14-G14-I14-H14 -> 3392.98 | K14: =13843+3000+1250-150+13+2500+3500+400 -> 24356 | L14: 1800 | M14: =IF(K14>21000,0,ROUND(K14*0.0325,0)) -> 0 | N14: =+K14+L14+M14 -> 26156 | P14: =+O14+N14 -> 26156 | Q14: 31 | R14: =ROUND(F14/$Q$1*Q14,0) -> 12178 | S14: =ROUND(G14/$Q$1*Q14,0) -> 6089 | T14: =ROUND(H14/$Q$1*Q14,0) -> 1600 | U14: =ROUND(I14/$Q$1*Q14,0) -> 1096 | V14: =ROUND(J14/$Q$1*Q14,0) -> 3393 | X14: =SUM(R14:V14) -> 24356 | Y14: =MIN(1800,IF(L14>0,ROUND((X14-S14)*0.12,0),0)) -> 1800 | Z14: =+IF(M14>0,ROUNDUP((X14)*0.0075,0),0) -> 0 | AA14: 5000 | AB14: =+SUM(Y14:AA14) -> 6800 | AC14: =+X14-AB14+W14 -> 17556 | AD14: ='Expenses '!AC12 -> 5000
B15: 5 | C15: Amit Kumar Rai | D15: 01.12.2021 | E15: Consortium | F15: =K15/2 -> 18350 | G15: =ROUND(+F15*0.5,0) -> 9175 | H15: 1600 | I15: =+F15*0.09 -> 1651.5 | J15: =K15-F15-G15-I15-H15 -> 5923.5 | K15: 36700 | L15: 1800 | M15: =IF(K15>21000,0,ROUND(K15*0.0325,0)) -> 0 | N15: =+K15+L15+M15 -> 38500 | P15: =+O15+N15 -> 38500 | Q15: 31 | R15: =ROUND(F15/$Q$1*Q15,0) -> 18350 | S15: =ROUND(G15/$Q$1*Q15,0) -> 9175 | T15: =ROUND(H15/$Q$1*Q15,0) -> 1600 | U15: =ROUND(I15/$Q$1*Q15,0) -> 1652 | V15: =ROUND(J15/$Q$1*Q15,0) -> 5924 | X15: =SUM(R15:V15) -> 36701 | Y15: =MIN(1800,IF(L15>0,ROUND((X15-S15)*0.12,0),0)) -> 1800 | Z15: =+IF(M15>0,ROUNDUP((X15)*0.0075,0),0) -> 0 | AA15: 5000 | AB15: =+SUM(Y15:AA15) -> 6800 | AC15: =+X15-AB15+W15 -> 29901 | AD15: ='Expenses '!AC13 -> 6500
A16: FNF | B16: 6 | C16: Aarti Sharma | D16: 01.05.2022 | E16: Consortium | F16: =K16/2 -> 14500 | G16: =ROUND(+F16*0.5,0) -> 7250 | H16: 1600 | I16: =+F16*0.09 -> 1305 | J16: =K16-F16-G16-I16-H16 -> 4345 | K16: =22000+7000 -> 29000 | M16: =IF(K16>21000,0,ROUND(K16*0.0325,0)) -> 0 | N16: =+K16+L16+M16 -> 29000 | P16: =+O16+N16 -> 29000 | Q16: 30 | R16: =ROUND(F16/$Q$1*Q16,0) -> 14032 | S16: =ROUND(G16/$Q$1*Q16,0) -> 7016 | T16: =ROUND(H16/$Q$1*Q16,0) -> 1548 | U16: =ROUND(I16/$Q$1*Q16,0) -> 1263 | V16: =ROUND(J16/$Q$1*Q16,0) -> 4205 | X16: =SUM(R16:V16) -> 28064 | Y16: =MIN(1800,IF(L16>0,ROUND((X16-S16)*0.12,0),0)) -> 0 | Z16: =+IF(M16>0,ROUNDUP((X16)*0.0075,0),0) -> 0 | AB16: =+SUM(Y16:AA16) -> 0 | AC16: =+X16-AB16+W16 -> 28064 | AD16: ='Expenses '!AC14 -> 2904
A17: FNF | B17: 7 | C17: Srishti Singh | D17: 12.07.2022 | E17: Consortium | F17: =K17/2 -> 12600 | G17: =ROUND(+F17*0.5,0) -> 6300 | H17: 1600 | I17: =+F17*0.09 -> 1134 | J17: =K17-F17-G17-I17-H17 -> 3566 | K17: =21500+5500-1800 -> 25200 | L17: 1800 | M17: =IF(K17>21000,0,ROUND(K17*0.0325,0)) -> 0 | N17: =+K17+L17+M17 -> 27000 | P17: =+O17+N17 -> 27000 | Q17: 12 | R17: =ROUND(F17/$Q$1*Q17,0) -> 4877 | S17: =ROUND(G17/$Q$1*Q17,0) -> 2439 | T17: =ROUND(H17/$Q$1*Q17,0) -> 619 | U17: =ROUND(I17/$Q$1*Q17,0) -> 439 | V17: =ROUND(J17/$Q$1*Q17,0) -> 1380 | X17: =SUM(R17:V17) -> 9754 | Y17: =MIN(1800,IF(L17>0,ROUND((X17-S17)*0.12,0),0)) -> 878 | Z17: =+IF(M17>0,ROUNDUP((X17)*0.0075,0),0) -> 0 | AB17: =+SUM(Y17:AA17) -> 878 | AC17: =+X17-AB17+W17 -> 8876 | AD17: ='Expenses '!AC15 -> 2710
B18: 8 | C18: Akash Kumar Gupta | D18: 15.11.2022 | E18: Consortium | F18: =K18/2 -> 8213.5 | G18: =ROUND(+F18*0.5,0) -> 4107 | H18: 1600 | I18: =+F18*0.09 -> 739.215 | J18: =K18-F18-G18-I18-H18 -> 1767.285 | K18: =13427+3000 -> 16427 | L18: =ROUND((K18-G18)*0.12,0) -> 1478 | M18: =IF(K18>21000,0,ROUND(K18*0.0325,0)) -> 534 | N18: =+K18+L18+M18 -> 18439 | O18: 0 | P18: =+O18+N18 -> 18439 | Q18: 31 | R18: =ROUND(F18/$Q$1*Q18,0) -> 8214 | S18: =ROUND(G18/$Q$1*Q18,0) -> 4107 | T18: =ROUND(H18/$Q$1*Q18,0) -> 1600 | U18: =ROUND(I18/$Q$1*Q18,0) -> 739 | V18: =ROUND(J18/$Q$1*Q18,0) -> 1767 | X18: =SUM(R18:V18) -> 16427 | Y18: =MIN(1800,IF(L18>0,ROUND((X18-S18)*0.12,0),0)) -> 1478 | Z18: =+IF(M18>0,ROUNDUP((X18)*0.0075,0),0) -> 124 | AB18: =+SUM(Y18:AA18) -> 1602 | AC18: =+X18-AB18+W18 -> 14825 | AD18: ='Expenses '!AC16 -> 6500
B19: 9 | C19: Chinku | D19: 18.11.2022 | E19: Consortium | F19: =K19/2 -> 7963.5 | G19: =ROUND(+F19*0.5,0) -> 3982 | H19: 1600 | I19: =+F19*0.09 -> 716.715 | J19: =K19-F19-G19-I19-H19 -> 1664.785 | K19: =13427+2500 -> 15927 | L19: =ROUND((K19-G19)*0.12,0) -> 1433 | M19: =IF(K19>21000,0,ROUND(K19*0.0325,0)) -> 518 | N19: =+K19+L19+M19 -> 17878 | O19: 0 | P19: =+O19+N19 -> 17878 | Q19: 31 | R19: =ROUND(F19/$Q$1*Q19,0) -> 7964 | S19: =ROUND(G19/$Q$1*Q19,0) -> 3982 | T19: =ROUND(H19/$Q$1*Q19,0) -> 1600 | U19: =ROUND(I19/$Q$1*Q19,0) -> 717 | V19: =ROUND(J19/$Q$1*Q19,0) -> 1665 | X19: =SUM(R19:V19) -> 15928 | Y19: =MIN(1800,IF(L19>0,ROUND((X19-S19)*0.12,0),0)) -> 1434 | Z19: =+IF(M19>0,ROUNDUP((X19)*0.0075,0),0) -> 120 | AB19: =+SUM(Y19:AA19) -> 1554 | AC19: =+X19-AB19+W19 -> 14374 | AD19: ='Expenses '!AC17 -> 3000
A20: FNF | B20: 10 | C20: Manish Singh | D20: 21.11.2022 | E20: Consortium | F20: =K20/2 -> 10679 | G20: =ROUND(+F20*0.5,0) -> 5340 | H20: 1600 | I20: =+F20*0.09 -> 961.11 | J20: =K20-F20-G20-I20-H20 -> 2777.89 | K20: 21358 | L20: 1800 | N20: =+K20+L20+M20 -> 23158 | P20: =+O20+N20 -> 23158 | Q20: 3 | R20: =ROUND(F20/$Q$1*Q20,0) -> 1033 | S20: =ROUND(G20/$Q$1*Q20,0) -> 517 | T20: =ROUND(H20/$Q$1*Q20,0) -> 155 | U20: =ROUND(I20/$Q$1*Q20,0) -> 93 | V20: =ROUND(J20/$Q$1*Q20,0) -> 269 | X20: =SUM(R20:V20) -> 2067 | Y20: =MIN(1800,IF(L20>0,ROUND((X20-S20)*0.12,0),0)) -> 186 | Z20: =+IF(M20>0,ROUNDUP((X20)*0.0075,0),0) -> 0 | AB20: =+SUM(Y20:AA20) -> 186 | AC20: =+X20-AB20+W20 -> 1881 | AD20: ='Expenses '!AC18 -> 0
B21: 11 | C21: Jaya Singh | D21: 01.01.2023 | E21: Consortium | F21: =K21/2 -> 10500 | G21: =ROUND(+F21*0.5,0) -> 5250 | H21: 1600 | I21: =+F21*0.09 -> 945 | J21: =K21-F21-G21-I21-H21 -> 2705 | K21: 21000 | L21: 1800 | N21: =+K21+L21+M21 -> 22800 | O21: 0 | P21: =+O21+N21 -> 22800 | Q21: 31 | R21: =ROUND(F21/$Q$1*Q21,0) -> 10500 | S21: =ROUND(G21/$Q$1*Q21,0) -> 5250 | T21: =ROUND(H21/$Q$1*Q21,0) -> 1600 | U21: =ROUND(I21/$Q$1*Q21,0) -> 945 | V21: =ROUND(J21/$Q$1*Q21,0) -> 2705 | X21: =SUM(R21:V21) -> 21000 | Y21: =MIN(1800,IF(L21>0,ROUND((X21-S21)*0.12,0),0)) -> 1800 | Z21: =+IF(M21>0,ROUNDUP((X21)*0.0075,0),0) -> 0 | AB21: =+SUM(Y21:AA21) -> 1800 | AC21: =+X21-AB21+W21 -> 19200 | AD21: ='Expenses '!AC19 -> 1800
B22: 12 | C22: Mansi Srivastava | D22: 01.04.2023 | E22: Consortium | F22: =K22/2 -> 10750 | G22: =ROUND(+F22*0.5,0) -> 5375 | H22: 1600 | I22: =+F22*0.09 -> 967.5 | J22: =K22-F22-G22-I22-H22 -> 2807.5 | K22: 21500 | L22: 0 | M22: =IF(K22>21000,0,ROUND(K22*0.0325,0)) -> 0 | N22: =+K22+L22+M22 -> 21500 | P22: =+O22+N22 -> 21500 | Q22: 31 | R22: =ROUND(F22/$Q$1*Q22,0) -> 10750 | S22: =ROUND(G22/$Q$1*Q22,0) -> 5375 | T22: =ROUND(H22/$Q$1*Q22,0) -> 1600 | U22: =ROUND(I22/$Q$1*Q22,0) -> 968 | V22: =ROUND(J22/$Q$1*Q22,0) -> 2808 | X22: =SUM(R22:V22) -> 21501 | Y22: =MIN(1800,IF(L22>0,ROUND((X22-S22)*0.12,0),0)) -> 0 | Z22: =+IF(M22>0,ROUNDUP((X22)*0.0075,0),0) -> 0 | AA22: 0 | AB22: =+SUM(Y22:AA22) -> 0 | AC22: =+X22-AB22+W22 -> 21501 | AD22: ='Expenses '!AC20 -> 3000
B23: 13 | C23: Navinder Singh Bisht | D23: 01.04.2023 | E23: Consortium | F23: =K23/2 -> 10750 | G23: =ROUND(+F23*0.5,0) -> 5375 | H23: 1600 | I23: =+F23*0.09 -> 967.5 | J23: =K23-F23-G23-I23-H23 -> 2807.5 | K23: =21500 -> 21500 | L23: 0 | M23: =IF(K23>21000,0,ROUND(K23*0.0325,0)) -> 0 | N23: =+K23+L23+M23 -> 21500 | P23: =+O23+N23 -> 21500 | Q23: 31 | R23: =ROUND(F23/$Q$1*Q23,0) -> 10750 | S23: =ROUND(G23/$Q$1*Q23,0) -> 5375 | T23: =ROUND(H23/$Q$1*Q23,0) -> 1600 | U23: =ROUND(I23/$Q$1*Q23,0) -> 968 | V23: =ROUND(J23/$Q$1*Q23,0) -> 2808 | X23: =SUM(R23:V23) -> 21501 | Y23: =MIN(1800,IF(L23>0,ROUND((X23-S23)*0.12,0),0)) -> 0 | Z23: =+IF(M23>0,ROUNDUP((X23)*0.0075,0),0) -> 0 | AB23: =+SUM(Y23:AA23) -> 0 | AC23: =+X23-AB23+W23 -> 21501 | AD23: ='Expenses '!AC21 -> 2000
B24: 14 | C24: Vivek Verma | D24: 01.04.2023 | E24: Consortium | F24: =K24/2 -> 11600 | G24: =ROUND(+F24*0.5,0) -> 5800 | H24: 1600 | I24: =+F24*0.09 -> 1044 | J24: =K24-F24-G24-I24-H24 -> 3156 | K24: 23200 | L24: 1800 | N24: =+K24+L24+M24 -> 25000 | P24: =+O24+N24 -> 25000 | Q24: 25.5 | R24: =ROUND(F24/$Q$1*Q24,0) -> 9542 | S24: =ROUND(G24/$Q$1*Q24,0) -> 4771 | T24: =ROUND(H24/$Q$1*Q24,0) -> 1316 | U24: =ROUND(I24/$Q$1*Q24,0) -> 859 | V24: =ROUND(J24/$Q$1*Q24,0) -> 2596 | X24: =SUM(R24:V24) -> 19084 | Y24: =MIN(1800,IF(L24>0,ROUND((X24-S24)*0.12,0),0)) -> 1718 | Z24: =+IF(M24>0,ROUNDUP((X24)*0.0075,0),0) -> 0 | AB24: =+SUM(Y24:AA24) -> 1718 | AC24: =+X24-AB24+W24 -> 17366 | AD24: ='Expenses '!AC22 -> 3290
B25: 15 | C25: Rishabh Pandey | D25: 01.05.2023 | E25: Consortium | F25: =K25/2 -> 11000 | G25: =ROUND(+F25*0.5,0) -> 5500 | H25: 1600 | I25: =+F25*0.09 -> 990 | J25: =K25-F25-G25-I25-H25 -> 2910 | K25: 22000 | N25: =+K25+L25+M25 -> 22000 | P25: =+O25+N25 -> 22000 | Q25: 31 | R25: =ROUND(F25/$Q$1*Q25,0) -> 11000 | S25: =ROUND(G25/$Q$1*Q25,0) -> 5500 | T25: =ROUND(H25/$Q$1*Q25,0) -> 1600 | U25: =ROUND(I25/$Q$1*Q25,0) -> 990 | V25: =ROUND(J25/$Q$1*Q25,0) -> 2910 | X25: =SUM(R25:V25) -> 22000 | Y25: =MIN(1800,IF(L25>0,ROUND((X25-S25)*0.12,0),0)) -> 0 | Z25: =+IF(M25>0,ROUNDUP((X25)*0.0075,0),0) -> 0 | AA25: 5000 | AB25: =+SUM(Y25:AA25) -> 5000 | AC25: =+X25-AB25+W25 -> 17000 | AD25: ='Expenses '!AC23 -> 4000
B26: 16 | C26: Neetu Raghav | D26: 01.05.2023 | E26: Consortium | F26: =K26/2 -> 10750 | G26: =ROUND(+F26*0.5,0) -> 5375 | H26: 1600 | I26: =+F26*0.09 -> 967.5 | J26: =K26-F26-G26-I26-H26 -> 2807.5 | K26: =21500 -> 21500 | N26: 21500 | P26: =+O26+N26 -> 21500 | Q26: 31 | R26: =ROUND(F26/$Q$1*Q26,0) -> 10750 | S26: =ROUND(G26/$Q$1*Q26,0) -> 5375 | T26: =ROUND(H26/$Q$1*Q26,0) -> 1600 | U26: =ROUND(I26/$Q$1*Q26,0) -> 968 | V26: =ROUND(J26/$Q$1*Q26,0) -> 2808 | X26: =SUM(R26:V26) -> 21501 | Y26: =MIN(1800,IF(L26>0,ROUND((X26-S26)*0.12,0),0)) -> 0 | Z26: =+IF(M26>0,ROUNDUP((X26)*0.0075,0),0) -> 0 | AA26: =5000 -> 5000 | AB26: =+SUM(Y26:AA26) -> 5000 | AC26: =+X26-AB26+W26 -> 16501 | AD26: ='Expenses '!AC24 -> 5000
B27: 17 | C27: Subham Gautam | D27: 01.12.2023 | E27: Consortium | F27: =K27/2 -> 8909 | G27: =ROUND(+F27*0.5,0) -> 4455 | H27: 1600 | I27: =+F27*0.09 -> 801.81 | J27: =K27-F27-G27-I27-H27 -> 2052.19 | K27: 17818 | L27: =ROUND((K27-G27)*0.12,0) -> 1604 | M27: =IF(K27>21000,0,ROUND(K27*0.0325,0)) -> 579 | N27: =+K27+L27+M27 -> 20001 | P27: =+O27+N27 -> 20001 | Q27: 21.5 | R27: =ROUND(F27/$Q$1*Q27,0) -> 6179 | S27: =ROUND(G27/$Q$1*Q27,0) -> 3090 | T27: =ROUND(H27/$Q$1*Q27,0) -> 1110 | U27: =ROUND(I27/$Q$1*Q27,0) -> 556 | V27: =ROUND(J27/$Q$1*Q27,0) -> 1423 | X27: =SUM(R27:V27) -> 12358 | Y27: =MIN(1800,IF(L27>0,ROUND((X27-S27)*0.12,0),0)) -> 1112 | Z27: =+IF(M27>0,ROUNDUP((X27)*0.0075,0),0) -> 93 | AB27: =+SUM(Y27:AA27) -> 1205 | AC27: =+X27-AB27+W27 -> 11153 | AD27: ='Expenses '!AC25 -> 1664
B28: 18 | C28: Taniya | D28: 01.07.2024 | E28: Consortium | F28: =K28/2 -> 11000 | G28: =ROUND(+F28*0.5,0) -> 5500 | H28: 1600 | I28: =+F28*0.09 -> 990 | J28: =K28-F28-G28-I28-H28 -> 2910 | K28: 22000 | L28: 0 | M28: =IF(K28>21000,0,ROUND(K28*0.0325,0)) -> 0 | N28: =+K28+L28+M28 -> 22000 | P28: =+O28+N28 -> 22000 | Q28: 31 | R28: =ROUND(F28/$Q$1*Q28,0) -> 11000 | S28: =ROUND(G28/$Q$1*Q28,0) -> 5500 | T28: =ROUND(H28/$Q$1*Q28,0) -> 1600 | U28: =ROUND(I28/$Q$1*Q28,0) -> 990 | V28: =ROUND(J28/$Q$1*Q28,0) -> 2910 | X28: =SUM(R28:V28) -> 22000 | Y28: =MIN(1800,IF(L28>0,ROUND((X28-S28)*0.12,0),0)) -> 0 | Z28: =+IF(M28>0,ROUNDUP((X28)*0.0075,0),0) -> 0 | AB28: =+SUM(Y28:AA28) -> 0 | AC28: =+X28-AB28+W28 -> 22000 | AD28: ='Expenses '!AC26 -> 6500
B29: 19 | C29: Mansi Poonia | D29: 01.07.2024 | E29: Consortium | F29: =K29/2 -> 11000 | G29: =ROUND(+F29*0.5,0) -> 5500 | H29: 1600 | I29: =+F29*0.09 -> 990 | J29: =K29-F29-G29-I29-H29 -> 2910 | K29: 22000 | L29: 0 | M29: =IF(K29>21000,0,ROUND(K29*0.0325,0)) -> 0 | N29: =+K29+L29+M29 -> 22000 | P29: =+O29+N29 -> 22000 | Q29: 27 | R29: =ROUND(F29/$Q$1*Q29,0) -> 9581 | S29: =ROUND(G29/$Q$1*Q29,0) -> 4790 | T29: =ROUND(H29/$Q$1*Q29,0) -> 1394 | U29: =ROUND(I29/$Q$1*Q29,0) -> 862 | V29: =ROUND(J29/$Q$1*Q29,0) -> 2535 | X29: =SUM(R29:V29) -> 19162 | Y29: =MIN(1800,IF(L29>0,ROUND((X29-S29)*0.12,0),0)) -> 0 | Z29: =+IF(M29>0,ROUNDUP((X29)*0.0075,0),0) -> 0 | AB29: =+SUM(Y29:AA29) -> 0 | AC29: =+X29-AB29+W29 -> 19162 | AD29: ='Expenses '!AC27 -> 5660
B30: 20 | C30: Gautam Goswami | D30: 20.07.2024 | E30: Consortium | F30: =K30/2 -> 19100 | G30: =ROUND(+F30*0.5,0) -> 9550 | H30: 1600 | I30: =+F30*0.09 -> 1719 | J30: =K30-F30-G30-I30-H30 -> 6231 | K30: 38200 | L30: 1800 | N30: =+K30+L30+M30 -> 40000 | P30: =+O30+N30 -> 40000 | Q30: 31 | R30: =ROUND(F30/$Q$1*Q30,0) -> 19100 | S30: =ROUND(G30/$Q$1*Q30,0) -> 9550 | T30: =ROUND(H30/$Q$1*Q30,0) -> 1600 | U30: =ROUND(I30/$Q$1*Q30,0) -> 1719 | V30: =ROUND(J30/$Q$1*Q30,0) -> 6231 | X30: =SUM(R30:V30) -> 38200 | Y30: =MIN(1800,IF(L30>0,ROUND((X30-S30)*0.12,0),0)) -> 1800 | Z30: =+IF(M30>0,ROUNDUP((X30)*0.0075,0),0) -> 0 | AB30: =+SUM(Y30:AA30) -> 1800 | AC30: =+X30-AB30+W30 -> 36400 | AD30: ='Expenses '!AC28 -> 7000 | AE30: UAN 100158762272
A31: FNF | B31: 21 | C31: Shivani Sonekar | D31: 21.02.2025 | E31: Consortium | F31: =K31/2 -> 11350 | G31: =ROUND(+F31*0.5,0) -> 5675 | H31: 1600 | I31: =+F31*0.09 -> 1021.5 | J31: =K31-F31-G31-I31-H31 -> 3053.5 | K31: 22700 | L31: 0 | M31: =IF(K31>21000,0,ROUND(K31*0.0325,0)) -> 0 | N31: =+K31+L31+M31 -> 22700 | P31: =+O31+N31 -> 22700 | Q31: 28 | R31: =ROUND(F31/$Q$1*Q31,0) -> 10252 | S31: =ROUND(G31/$Q$1*Q31,0) -> 5126 | T31: =ROUND(H31/$Q$1*Q31,0) -> 1445 | U31: =ROUND(I31/$Q$1*Q31,0) -> 923 | V31: =ROUND(J31/$Q$1*Q31,0) -> 2758 | X31: =SUM(R31:V31) -> 20504 | Y31: =MIN(1800,IF(L31>0,ROUND((X31-S31)*0.12,0),0)) -> 0 | Z31: =+IF(M31>0,ROUNDUP((X31)*0.0075,0),0) -> 0 | AB31: =+SUM(Y31:AA31) -> 0 | AC31: =+X31-AB31+W31 -> 20504 | AD31: ='Expenses '!AC29 -> 0
B32: 22 | C32: Rashika Yadav | D32: 11-07-2025 | E32: Consortium | F32: =K32/2 -> 8018 | G32: =ROUND(+F32*0.5,0) -> 4009 | H32: 1600 | I32: =+F32*0.09 -> 721.62 | J32: =K32-F32-G32-I32-H32 -> 1687.38 | K32: 16036 | L32: =ROUND((K32-G32)*0.12,0) -> 1443 | M32: =IF(K32>21000,0,ROUND(K32*0.0325,0)) -> 521 | N32: =+K32+L32+M32 -> 18000 | P32: =+O32+N32 -> 18000 | Q32: 31 | R32: =ROUND(F32/$Q$1*Q32,0) -> 8018 | S32: =ROUND(G32/$Q$1*Q32,0) -> 4009 | T32: =ROUND(H32/$Q$1*Q32,0) -> 1600 | U32: =ROUND(I32/$Q$1*Q32,0) -> 722 | V32: =ROUND(J32/$Q$1*Q32,0) -> 1687 | X32: =SUM(R32:V32) -> 16036 | Y32: =MIN(1800,IF(L32>0,ROUND((X32-S32)*0.12,0),0)) -> 1443 | Z32: =+IF(M32>0,ROUNDUP((X32)*0.0075,0),0) -> 121 | AB32: =+SUM(Y32:AA32) -> 1564 | AC32: =+X32-AB32+W32 -> 14472 | AD32: ='Expenses '!AC30 -> 0
B33: 23 | C33: Aparna Balchandran | D33: 17-07-2025 | E33: Consortium | F33: =K33/2 -> 9518 | G33: =ROUND(+F33*0.5,0) -> 4759 | H33: 1600 | I33: =+F33*0.09 -> 856.62 | J33: =K33-F33-G33-I33-H33 -> 2302.38 | K33: =16036+3000 -> 19036 | L33: =ROUND((K33-G33)*0.12,0) -> 1713 | N33: =+K33+L33+M33 -> 20749 | P33: =+O33+N33 -> 20749 | Q33: 30 | R33: =ROUND(F33/$Q$1*Q33,0) -> 9211 | S33: =ROUND(G33/$Q$1*Q33,0) -> 4605 | T33: =ROUND(H33/$Q$1*Q33,0) -> 1548 | U33: =ROUND(I33/$Q$1*Q33,0) -> 829 | V33: =ROUND(J33/$Q$1*Q33,0) -> 2228 | X33: =SUM(R33:V33) -> 18421 | Y33: =MIN(1800,IF(L33>0,ROUND((X33-S33)*0.12,0),0)) -> 1658 | Z33: =+IF(M33>0,ROUNDUP((X33)*0.0075,0),0) -> 0 | AB33: =+SUM(Y33:AA33) -> 1658 | AC33: =+X33-AB33+W33 -> 16763 | AD33: ='Expenses '!AC31 -> 0 | AE33: INC 3k
B34: 24 | C34: Neha Durga | D34: 01-11-2025 | E34: Consortium | F34: =K34/2 -> 14000 | G34: =ROUND(+F34*0.5,0) -> 7000 | H34: 1600 | I34: =+F34*0.09 -> 1260 | J34: =K34-F34-G34-I34-H34 -> 4140 | K34: 28000 | L34: 1800 | M34: =IF(K34>21000,0,ROUND(K34*0.0325,0)) -> 0 | N34: =+K34+L34+M34 -> 29800 | P34: =+O34+N34 -> 29800 | Q34: 31 | R34: =ROUND(F34/$Q$1*Q34,0) -> 14000 | S34: =ROUND(G34/$Q$1*Q34,0) -> 7000 | T34: =ROUND(H34/$Q$1*Q34,0) -> 1600 | U34: =ROUND(I34/$Q$1*Q34,0) -> 1260 | V34: =ROUND(J34/$Q$1*Q34,0) -> 4140 | X34: =SUM(R34:V34) -> 28000 | Y34: =MIN(1800,IF(L34>0,ROUND((X34-S34)*0.12,0),0)) -> 1800 | Z34: =+IF(M34>0,ROUNDUP((X34)*0.0075,0),0) -> 0 | AB34: =+SUM(Y34:AA34) -> 1800 | AC34: =+X34-AB34+W34 -> 26200
B35: 25 | C35: Vanshika Kardam | D35: 01-12-2025 | E35: Consortium | F35: =K35/2 -> 9000 | G35: =ROUND(+F35*0.5,0) -> 4500 | H35: 1600 | I35: =+F35*0.09 -> 810 | J35: =K35-F35-G35-I35-H35 -> 2090 | K35: 18000 | L35: =ROUND((K35-G35)*0.12,0) -> 1620 | M35: =IF(K35>21000,0,ROUND(K35*0.0325,0)) -> 585 | N35: =+K35+L35+M35 -> 20205 | P35: =+O35+N35 -> 20205 | Q35: 31 | R35: =ROUND(F35/$Q$1*Q35,0) -> 9000 | S35: =ROUND(G35/$Q$1*Q35,0) -> 4500 | T35: =ROUND(H35/$Q$1*Q35,0) -> 1600 | U35: =ROUND(I35/$Q$1*Q35,0) -> 810 | V35: =ROUND(J35/$Q$1*Q35,0) -> 2090 | X35: =SUM(R35:V35) -> 18000 | Y35: =MIN(1800,IF(L35>0,ROUND((X35-S35)*0.12,0),0)) -> 1620 | Z35: =+IF(M35>0,ROUNDUP((X35)*0.0075,0),0) -> 135 | AB35: =+SUM(Y35:AA35) -> 1755 | AC35: =+X35-AB35+W35 -> 16245 | AE35: UAN102278611079
B36: 26 | C36: Rohan Gautam | D36: 01-12-2025 | E36: Consortium | F36: =K36/2 -> 11000 | G36: =ROUND(+F36*0.5,0) -> 5500 | H36: 1600 | I36: =+F36*0.09 -> 990 | J36: =K36-F36-G36-I36-H36 -> 2910 | K36: 22000 | L36: 1800 | M36: =IF(K36>21000,0,ROUND(K36*0.0325,0)) -> 0 | N36: =+K36+L36+M36 -> 23800 | P36: =+O36+N36 -> 23800 | Q36: 31 | R36: =ROUND(F36/$Q$1*Q36,0) -> 11000 | S36: =ROUND(G36/$Q$1*Q36,0) -> 5500 | T36: =ROUND(H36/$Q$1*Q36,0) -> 1600 | U36: =ROUND(I36/$Q$1*Q36,0) -> 990 | V36: =ROUND(J36/$Q$1*Q36,0) -> 2910 | W36: 7000 | X36: =SUM(R36:V36) -> 22000 | Y36: =MIN(1800,IF(L36>0,ROUND((X36-S36)*0.12,0),0)) -> 1800 | Z36: =+IF(M36>0,ROUNDUP((X36)*0.0075,0),0) -> 0 | AB36: =+SUM(Y36:AA36) -> 1800 | AC36: =+X36-AB36+W36 -> 27200 | AE36: UAN102286813904
E37: TOTAL | F37: =SUM(F11:F36) -> 321820 | G37: =SUM(G11:G36) -> 160911 | H37: =SUM(H11:H36) -> 41600 | I37: =SUM(I11:I36) -> 28963.8 | J37: =SUM(J11:J36) -> 90345.2 | K37: =SUM(K11:K36) -> 643640 | L37: =SUM(L11:L36) -> 29091 | M37: =SUM(M11:M36) -> 2737 | N37: =SUM(N11:N36) -> 675468 | O37: =SUM(O11:O33) -> 0 | P37: =SUM(P11:P36) -> 675468 | R37: =SUM(R11:R36) -> 296373 | S37: =SUM(S11:S36) -> 148186 | T37: =SUM(T11:T36) -> 37935 | U37: =SUM(U11:U36) -> 26677 | V37: =SUM(V11:V36) -> 83577 | W37: =SUM(W11:W36) -> 7000 | X37: =SUM(X11:X36) -> 592748 | Y37: =SUM(Y11:Y36) -> 31002 | ... AC37: =SUM(AC11:AC36) -> 546153 | AD37: ='Expenses '!AC35 -> 82028 | AE37: =AC37+AD37 -> 628181
D38: GRAND TOTAL | F38: =+F37+F9 -> 358009.5 | G38: =+G37+G9 -> 179006 | H38: =+H37+H9 -> 46401 | I38: =+I37+I9 -> 32220.855 | J38: =+J37+J9 -> 100381.65 | K38: =+K37+K9 -> 716019 | L38: =+L37+L9 -> 32005 | M38: =+M37+M9 -> 2737 | ... P38: =+P37+P9 -> 750761 | R38: =+R37+R9 -> 326853 | S38: =+S37+S9 -> 163427 | T38: =+T37+T9 -> 42194 | U38: =+U37+U9 -> 29421 | V38: =+V37+V9 -> 91814 | W38: =+W37+W9 -> 13589 | X38: =+X37+X9 -> 653709 | Y38: =+Y37+Y9 -> 33759 | ... AD38: =+AD37+AD9 -> 83528
S44: Reinste | T44: Net Salary | U44: =AC9+AD9 -> 61293 | Z44: Consortium | AB44: Net salary | AC44: =AC37+AD37 -> 628181
Z45: Individual chq | AB45: Less Individual chq | AC45: =AA48 -> 57902
...

Sheet Expenses 
Q1: =+Salary!Q1 -> 31
Q2: =+Salary!Q2 -> Salary for the month of December 2025
F3: Monthly CTC for Employees | Q3: Gross Earnings | Y3: Advance
B4: S.No. | C4: NAME OF EMPLOYEE | D4: DOJ | E4: Entity | F4: Health Care | G4: Travelling | H4: Mobile | I4: Internet | J4: Books & Periodicals | K4: Total Entitlement | N4: Total | O4: Others | P4: Gross Total | Q4: Pay Days | R4: =+F4 -> Health Care | S4: =G4 -> Travelling | T4: =H4 -> Mobile | U4: =I4 -> Internet | V4: =J4 -> Books & Periodicals | W4: Incentive /Others | X4: Total | AC4: Net Payable
C5: Reinste
B6: 1 | C6: Gulab | D6: 01.06.2018 | E6: Reinste | F6: =+K6*30% -> 450 | G6: =+K6*20% -> 300 | H6: =+K6*20% -> 300 | I6: =+K6*20% -> 300 | J6: =+K6*10% -> 150 | K6: 1500 | N6: =+K6+L6+M6 -> 1500 | P6: =+O6+N6 -> 1500 | Q6: =Salary!Q6 -> 31 | R6: =ROUND(F6/$Q$1*Q6,0) -> 450 | S6: =ROUND(G6/$Q$1*Q6,0) -> 300 | T6: =ROUND(H6/$Q$1*Q6,0) -> 300 | U6: =ROUND(I6/$Q$1*Q6,0) -> 300 | V6: =ROUND(J6/$Q$1*Q6,0) -> 150 | X6: =SUM(R6:V6) -> 1500 | Y6: =MIN(1800,IF(L6>0,ROUND((X6-S6)*0.12,0),0)) -> 0 | Z6: =+IF(M6>0,ROUNDUP((X6)*0.0175,0),0) -> 0 | AB6: =+SUM(Y6:AA6) -> 0 | AC6: =+X6-AB6+W6 -> 1500
E7: TOTAL | F7: =SUM(F6:F6) -> 450 | G7: =SUM(G6:G6) -> 300 | H7: =SUM(H6:H6) -> 300 | I7: =SUM(I6:I6) -> 300 | J7: =SUM(J6:J6) -> 150 | K7: =SUM(K6:K6) -> 1500 | N7: =SUM(N6:N6) -> 1500 | O7: =SUM(O6:O6) -> 0 | P7: =SUM(P6:P6) -> 1500 | R7: =SUM(R6:R6) -> 450 | S7: =SUM(S6:S6) -> 300 | U7: =SUM(U6:U6) -> 300 | V7: =SUM(V6:V6) -> 150 | W7: =SUM(W6:W6) -> 0 | X7: =SUM(X6:X6) -> 1500 | Y7: =SUM(Y6:Y6) -> 0 | Z7: =SUM(Z6:Z6) -> 0 | AA7: =SUM(AA6:AA6) -> 0 | AB7: =SUM(AB6:AB6) -> 0 | AC7: =SUM(AC6:AC6) -> 1500
C8: Consortiun
B9: 1 | C9: =Salary!C11 -> Asan Kumar | D9: =Salary!D11 -> 13.04.2012 | E9: Consortiun | F9: =+K9*30% -> 1950 | G9: =+K9*20% -> 1300 | H9: =+K9*20% -> 1300 | I9: =+K9*20% -> 1300 | J9: =+K9*10% -> 650 | K9: 6500 | N9: =+K9+L9+M9 -> 6500 | P9: =+O9+N9 -> 6500 | Q9: =Salary!Q11 -> 31 | R9: =ROUND(F9/$Q$1*Q9,0) -> 1950 | S9: =ROUND(G9/$Q$1*Q9,0) -> 1300 | T9: =ROUND(H9/$Q$1*Q9,0) -> 1300 | U9: =ROUND(I9/$Q$1*Q9,0) -> 1300 | V9: =ROUND(J9/$Q$1*Q9,0) -> 650 | X9: =SUM(R9:V9) -> 6500 | AB9: =+SUM(Y9:AA9) -> 0 | AC9: =+X9-AB9+W9 -> 6500
B10: 2 | C10: =Salary!C12 -> Ashwani Kumar | D10: 23.05.2010 | E10: Consortium | F10: =+K10*30% -> 900 | G10: =+K10*20% -> 600 | H10: =+K10*20% -> 600 | I10: =+K10*20% -> 600 | J10: =+K10*10% -> 300 | K10: 3000 | N10: =+K10+L10+M10 -> 3000 | P10: =+O10+N10 -> 3000 | Q10: =Salary!Q12 -> 31 | R10: =ROUND(F10/$Q$1*Q10,0) -> 900 | S10: =ROUND(G10/$Q$1*Q10,0) -> 600 | T10: =ROUND(H10/$Q$1*Q10,0) -> 600 | U10: =ROUND(I10/$Q$1*Q10,0) -> 600 | V10: =ROUND(J10/$Q$1*Q10,0) -> 300 | X10: =SUM(R10:V10) -> 3000 | AB10: =+SUM(Y10:AA10) -> 0 | AC10: =+X10-AB10+W10 -> 3000
B11: 3 | C11: =Salary!C13 -> Quaisher Hossain | D11: 14.03.2016 | E11: Consortium | F11: =+K11*30% -> 1800 | G11: =+K11*20% -> 1200 | H11: =+K11*20% -> 1200 | I11: =+K11*20% -> 1200 | J11: =+K11*10% -> 600 | K11: 6000 | N11: =+K11+L11+M11 -> 6000 | P11: =+O11+N11 -> 6000 | Q11: =Salary!Q13 -> 31 | R11: =ROUND(F11/$Q$1*Q11,0) -> 1800 | S11: =ROUND(G11/$Q$1*Q11,0) -> 1200 | T11: =ROUND(H11/$Q$1*Q11,0) -> 1200 | U11: =ROUND(I11/$Q$1*Q11,0) -> 1200 | V11: =ROUND(J11/$Q$1*Q11,0) -> 600 | X11: =SUM(R11:V11) -> 6000 | AB11: =+SUM(Y11:AA11) -> 0 | AC11: =+X11-AB11+W11 -> 6000
B12: 4 | C12: =Salary!C14 -> Gagan Kumar | D12: 01.01.2021 | E12: Consortium | F12: =+K12*30% -> 1500 | G12: =+K12*20% -> 1000 | H12: =+K12*20% -> 1000 | I12: =+K12*20% -> 1000 | J12: =+K12*10% -> 500 | K12: 5000 | N12: =+K12+L12+M12 -> 5000 | P12: =+O12+N12 -> 5000 | Q12: =Salary!Q14 -> 31 | R12: =ROUND(F12/$Q$1*Q12,0) -> 1500 | S12: =ROUND(G12/$Q$1*Q12,0) -> 1000 | T12: =ROUND(H12/$Q$1*Q12,0) -> 1000 | U12: =ROUND(I12/$Q$1*Q12,0) -> 1000 | V12: =ROUND(J12/$Q$1*Q12,0) -> 500 | X12: =SUM(R12:V12) -> 5000 | AB12: =+SUM(Y12:AA12) -> 0 | AC12: =+X12-AB12+W12 -> 5000
B13: 5 | C13: =Salary!C15 -> Amit Kumar Rai | D13: 01.12.2021 | E13: Consortium | F13: =+K13*30% -> 1950 | G13: =+K13*20% -> 1300 | H13: =+K13*20% -> 1300 | I13: =+K13*20% -> 1300 | J13: =+K13*10% -> 650 | K13: 6500 | N13: =+K13+L13+M13 -> 6500 | P13: =+O13+N13 -> 6500 | Q13: =Salary!Q15 -> 31 | R13: =ROUND(F13/$Q$1*Q13,0) -> 1950 | S13: =ROUND(G13/$Q$1*Q13,0) -> 1300 | T13: =ROUND(H13/$Q$1*Q13,0) -> 1300 | U13: =ROUND(I13/$Q$1*Q13,0) -> 1300 | V13: =ROUND(J13/$Q$1*Q13,0) -> 650 | X13: =SUM(R13:V13) -> 6500 | AB13: =+SUM(Y13:AA13) -> 0 | AC13: =+X13-AB13+W13 -> 6500 | AD13: Ch.No. 000
B14: 6 | C14: =Salary!C16 -> Aarti Sharma | D14: 01.05.2022 | E14: Consortium | F14: =+K14*30% -> 900 | G14: =+K14*20% -> 600 | H14: =+K14*20% -> 600 | I14: =+K14*20% -> 600 | J14: =+K14*10% -> 300 | K14: 3000 | N14: =+K14+L14+M14 -> 3000 | P14: =+O14+N14 -> 3000 | Q14: =Salary!Q16 -> 30 | R14: =ROUND(F14/$Q$1*Q14,0) -> 871 | S14: =ROUND(G14/$Q$1*Q14,0) -> 581 | T14: =ROUND(H14/$Q$1*Q14,0) -> 581 | U14: =ROUND(I14/$Q$1*Q14,0) -> 581 | V14: =ROUND(J14/$Q$1*Q14,0) -> 290 | X14: =SUM(R14:V14) -> 2904 | AB14: =+SUM(Y14:AA14) -> 0 | AC14: =+X14-AB14+W14 -> 2904
B15: 7 | C15: =Salary!C17 -> Srishti Singh | D15: 12.07.2022 | E15: Consortium | F15: =+K15*30% -> 2100 | G15: =+K15*20% -> 1400 | H15: =+K15*20% -> 1400 | I15: =+K15*20% -> 1400 | J15: =+K15*10% -> 700 | K15: 7000 | N15: =+K15+L15+M15 -> 7000 | P15: =+O15+N15 -> 7000 | Q15: =Salary!Q17 -> 12 | R15: =ROUND(F15/$Q$1*Q15,0) -> 813 | S15: =ROUND(G15/$Q$1*Q15,0) -> 542 | T15: =ROUND(H15/$Q$1*Q15,0) -> 542 | U15: =ROUND(I15/$Q$1*Q15,0) -> 542 | V15: =ROUND(J15/$Q$1*Q15,0) -> 271 | X15: =SUM(R15:V15) -> 2710 | AB15: =+SUM(Y15:AA15) -> 0 | AC15: =+X15-AB15+W15 -> 2710
B16: 8 | C16: =Salary!C18 -> Akash Kumar Gupta | D16: 15.11.2022 | E16: Consortium | F16: =+K16*30% -> 1950 | G16: =+K16*20% -> 1300 | H16: =+K16*20% -> 1300 | I16: =+K16*20% -> 1300 | J16: =+K16*10% -> 650 | K16: =4000+2500 -> 6500 | N16: =+K16+L16+M16 -> 6500 | P16: =+O16+N16 -> 6500 | Q16: =Salary!Q18 -> 31 | R16: =ROUND(F16/$Q$1*Q16,0) -> 1950 | S16: =ROUND(G16/$Q$1*Q16,0) -> 1300 | T16: =ROUND(H16/$Q$1*Q16,0) -> 1300 | U16: =ROUND(I16/$Q$1*Q16,0) -> 1300 | V16: =ROUND(J16/$Q$1*Q16,0) -> 650 | X16: =SUM(R16:V16) -> 6500 | AB16: =+SUM(Y16:AA16) -> 0 | AC16: =+X16-AB16+W16 -> 6500
B17: 9 | C17: =Salary!C19 -> Chinku | D17: 18.11.2022 | E17: Consortium | F17: =+K17*30% -> 900 | G17: =+K17*20% -> 600 | H17: =+K17*20% -> 600 | I17: =+K17*20% -> 600 | J17: =+K17*10% -> 300 | K17: 3000 | N17: =+K17+L17+M17 -> 3000 | P17: =+O17+N17 -> 3000 | Q17: =Salary!Q19 -> 31 | R17: =ROUND(F17/$Q$1*Q17,0) -> 900 | S17: =ROUND(G17/$Q$1*Q17,0) -> 600 | T17: =ROUND(H17/$Q$1*Q17,0) -> 600 | U17: =ROUND(I17/$Q$1*Q17,0) -> 600 | V17: =ROUND(J17/$Q$1*Q17,0) -> 300 | X17: =SUM(R17:V17) -> 3000 | AB17: =+SUM(Y17:AA17) -> 0 | AC17: =+X17-AB17+W17 -> 3000
B18: 10 | C18: =Salary!C20 -> Manish Singh | D18: 21.11.2022 | E18: Consortium | F18: =+K18*30% -> 0 | G18: =+K18*20% -> 0 | H18: =+K18*20% -> 0 | I18: =+K18*20% -> 0 | J18: =+K18*10% -> 0 | N18: =+K18+L18+M18 -> 0 | P18: =+O18+N18 -> 0 | Q18: =Salary!Q20 -> 3 | R18: =ROUND(F18/$Q$1*Q18,0) -> 0 | S18: =ROUND(G18/$Q$1*Q18,0) -> 0 | T18: =ROUND(H18/$Q$1*Q18,0) -> 0 | U18: =ROUND(I18/$Q$1*Q18,0) -> 0 | V18: =ROUND(J18/$Q$1*Q18,0) -> 0 | X18: =SUM(R18:V18) -> 0 | AB18: =+SUM(Y18:AA18) -> 0 | AC18: =+X18-AB18+W18 -> 0
B19: 11 | C19: =Salary!C21 -> Jaya Singh | D19: 01.01.2023 | E19: Consortium | F19: =+K19*30% -> 540 | G19: =+K19*20% -> 360 | H19: =+K19*20% -> 360 | I19: =+K19*20% -> 360 | J19: =+K19*10% -> 180 | K19: 1800 | N19: =+K19+L19+M19 -> 1800 | P19: =+O19+N19 -> 1800 | Q19: =Salary!Q21 -> 31 | R19: =ROUND(F19/$Q$1*Q19,0) -> 540 | S19: =ROUND(G19/$Q$1*Q19,0) -> 360 | T19: =ROUND(H19/$Q$1*Q19,0) -> 360 | U19: =ROUND(I19/$Q$1*Q19,0) -> 360 | V19: =ROUND(J19/$Q$1*Q19,0) -> 180 | X19: =SUM(R19:V19) -> 1800 | AB19: =+SUM(Y19:AA19) -> 0 | AC19: =+X19-AB19+W19 -> 1800
B20: 12 | C20: =Salary!C22 -> Mansi Srivastava | D20: 01.04.2023 | E20: Consortium | F20: =+K20*30% -> 900 | G20: =+K20*20% -> 600 | H20: =+K20*20% -> 600 | I20: =+K20*20% -> 600 | J20: =+K20*10% -> 300 | K20: 3000 | N20: =+K20+L20+M20 -> 3000 | P20: =+O20+N20 -> 3000 | Q20: =Salary!Q22 -> 31 | R20: =ROUND(F20/$Q$1*Q20,0) -> 900 | S20: =ROUND(G20/$Q$1*Q20,0) -> 600 | T20: =ROUND(H20/$Q$1*Q20,0) -> 600 | U20: =ROUND(I20/$Q$1*Q20,0) -> 600 | V20: =ROUND(J20/$Q$1*Q20,0) -> 300 | X20: =SUM(R20:V20) -> 3000 | AB20: =+SUM(Y20:AA20) -> 0 | AC20: =+X20-AB20+W20 -> 3000
B21: 13 | C21: =Salary!C23 -> Navinder Singh Bisht | D21: 01.04.2023 | E21: Consortium | F21: =+K21*30% -> 600 | G21: =+K21*20% -> 400 | H21: =+K21*20% -> 400 | I21: =+K21*20% -> 400 | J21: =+K21*10% -> 200 | K21: 2000 | N21: =+K21+L21+M21 -> 2000 | P21: =+O21+N21 -> 2000 | Q21: =Salary!Q23 -> 31 | R21: =ROUND(F21/$Q$1*Q21,0) -> 600 | S21: =ROUND(G21/$Q$1*Q21,0) -> 400 | T21: =ROUND(H21/$Q$1*Q21,0) -> 400 | U21: =ROUND(I21/$Q$1*Q21,0) -> 400 | V21: =ROUND(J21/$Q$1*Q21,0) -> 200 | X21: =SUM(R21:V21) -> 2000 | AB21: =+SUM(Y21:AA21) -> 0 | AC21: =+X21-AB21+W21 -> 2000
B22: 14 | C22: =Salary!C24 -> Vivek Verma | D22: 01.04.2023 | E22: Consortium | F22: =+K22*30% -> 1200 | G22: =+K22*20% -> 800 | H22: =+K22*20% -> 800 | I22: =+K22*20% -> 800 | J22: =+K22*10% -> 400 | K22: 4000 | N22: =+K22+L22+M22 -> 4000 | P22: =+O22+N22 -> 4000 | Q22: =Salary!Q24 -> 25.5 | R22: =ROUND(F22/$Q$1*Q22,0) -> 987 | S22: =ROUND(G22/$Q$1*Q22,0) -> 658 | T22: =ROUND(H22/$Q$1*Q22,0) -> 658 | U22: =ROUND(I22/$Q$1*Q22,0) -> 658 | V22: =ROUND(J22/$Q$1*Q22,0) -> 329 | X22: =SUM(R22:V22) -> 3290 | AB22: =+SUM(Y22:AA22) -> 0 | AC22: =+X22-AB22+W22 -> 3290
B23: 15 | C23: =Salary!C25 -> Rishabh Pandey | D23: 01.05.2023 | E23: Consortium | F23: =+K23*30% -> 1200 | G23: =+K23*20% -> 800 | H23: =+K23*20% -> 800 | I23: =+K23*20% -> 800 | J23: =+K23*10% -> 400 | K23: 4000 | N23: =+K23+L23+M23 -> 4000 | P23: =+O23+N23 -> 4000 | Q23: =Salary!Q25 -> 31 | R23: =ROUND(F23/$Q$1*Q23,0) -> 1200 | S23: =ROUND(G23/$Q$1*Q23,0) -> 800 | T23: =ROUND(H23/$Q$1*Q23,0) -> 800 | U23: =ROUND(I23/$Q$1*Q23,0) -> 800 | V23: =ROUND(J23/$Q$1*Q23,0) -> 400 | X23: =SUM(R23:V23) -> 4000 | AB23: =+SUM(Y23:AA23) -> 0 | AC23: =+X23-AB23+W23 -> 4000
B24: 16 | C24: =Salary!C26 -> Neetu Raghav | D24: 01.05.2023 | E24: Consortium | F24: =+K24*30% -> 1500 | G24: =+K24*20% -> 1000 | H24: =+K24*20% -> 1000 | I24: =+K24*20% -> 1000 | J24: =+K24*10% -> 500 | K24: 5000 | N24: =+K24+L24+M24 -> 5000 | P24: =+O24+N24 -> 5000 | Q24: =Salary!Q26 -> 31 | R24: =ROUND(F24/$Q$1*Q24,0) -> 1500 | S24: =ROUND(G24/$Q$1*Q24,0) -> 1000 | T24: =ROUND(H24/$Q$1*Q24,0) -> 1000 | U24: =ROUND(I24/$Q$1*Q24,0) -> 1000 | V24: =ROUND(J24/$Q$1*Q24,0) -> 500 | X24: =SUM(R24:V24) -> 5000 | AB24: =+SUM(Y24:AA24) -> 0 | AC24: =+X24-AB24+W24 -> 5000 | AD24: Ch.No.000
B25: 17 | C25: =Salary!C27 -> Subham Gautam | D25: 01.12.2023 | E25: Consortium | F25: =+K25*30% -> 720 | G25: =+K25*20% -> 480 | H25: =+K25*20% -> 480 | I25: =+K25*20% -> 480 | J25: =+K25*10% -> 240 | K25: 2400 | N25: =+K25+L25+M25 -> 2400 | P25: =+O25+N25 -> 2400 | Q25: =Salary!Q27 -> 21.5 | R25: =ROUND(F25/$Q$1*Q25,0) -> 499 | S25: =ROUND(G25/$Q$1*Q25,0) -> 333 | T25: =ROUND(H25/$Q$1*Q25,0) -> 333 | U25: =ROUND(I25/$Q$1*Q25,0) -> 333 | V25: =ROUND(J25/$Q$1*Q25,0) -> 166 | X25: =SUM(R25:V25) -> 1664 | AB25: =+SUM(Y25:AA25) -> 0 | AC25: =+X25-AB25+W25 -> 1664
B26: 19 | C26: =Salary!C28 -> Taniya | D26: 13.06.2024 | E26: Consortium | F26: =+K26*30% -> 1950 | G26: =+K26*20% -> 1300 | H26: =+K26*20% -> 1300 | I26: =+K26*20% -> 1300 | J26: =+K26*10% -> 650 | K26: 6500 | N26: =+K26+L26+M26 -> 6500 | P26: =+O26+N26 -> 6500 | Q26: =Salary!Q28 -> 31 | R26: =ROUND(F26/$Q$1*Q26,0) -> 1950 | S26: =ROUND(G26/$Q$1*Q26,0) -> 1300 | T26: =ROUND(H26/$Q$1*Q26,0) -> 1300 | U26: =ROUND(I26/$Q$1*Q26,0) -> 1300 | V26: =ROUND(J26/$Q$1*Q26,0) -> 650 | X26: =SUM(R26:V26) -> 6500 | AB26: =+SUM(Y26:AA26) -> 0 | AC26: =+X26-AB26+W26 -> 6500
B27: 20 | C27: =Salary!C29 -> Mansi Poonia | D27: 13.06.2024 | E27: Consortium | F27: =+K27*30% -> 1950 | G27: =+K27*20% -> 1300 | H27: =+K27*20% -> 1300 | I27: =+K27*20% -> 1300 | J27: =+K27*10% -> 650 | K27: 6500 | N27: =+K27+L27+M27 -> 6500 | P27: =+O27+N27 -> 6500 | Q27: =Salary!Q29 -> 27 | R27: =ROUND(F27/$Q$1*Q27,0) -> 1698 | S27: =ROUND(G27/$Q$1*Q27,0) -> 1132 | T27: =ROUND(H27/$Q$1*Q27,0) -> 1132 | U27: =ROUND(I27/$Q$1*Q27,0) -> 1132 | V27: =ROUND(J27/$Q$1*Q27,0) -> 566 | X27: =SUM(R27:V27) -> 5660 | AB27: =+SUM(Y27:AA27) -> 0 | AC27: =+X27-AB27+W27 -> 5660
B28: 21 | C28: =Salary!C30 -> Gautam Goswami | D28: =Salary!D30 -> 20.07.2024 | E28: Consortium | F28: =+K28*30% -> 2100 | G28: =+K28*20% -> 1400 | H28: =+K28*20% -> 1400 | I28: =+K28*20% -> 1400 | J28: =+K28*10% -> 700 | K28: 7000 | N28: =+K28+L28+M28 -> 7000 | P28: =+O28+N28 -> 7000 | Q28: =Salary!Q30 -> 31 | R28: =ROUND(F28/$Q$1*Q28,0) -> 2100 | S28: =ROUND(G28/$Q$1*Q28,0) -> 1400 | T28: =ROUND(H28/$Q$1*Q28,0) -> 1400 | U28: =ROUND(I28/$Q$1*Q28,0) -> 1400 | V28: =ROUND(J28/$Q$1*Q28,0) -> 700 | X28: =SUM(R28:V28) -> 7000 | AB28: =+SUM(Y28:AA28) -> 0 | AC28: =+X28-AB28+W28 -> 7000
B29: 22 | C29: =Salary!C31 -> Shivani Sonekar | D29: =Salary!D31 -> 21.02.2025 | E29: Consortium | F29: =+K29*30% -> 0 | G29: =+K29*20% -> 0 | H29: =+K29*20% -> 0 | I29: =+K29*20% -> 0 | J29: =+K29*10% -> 0 | N29: =+K29+L29+M29 -> 0 | P29: =+O29+N29 -> 0 | Q29: =Salary!Q31 -> 28 | R29: =ROUND(F29/$Q$1*Q29,0) -> 0 | S29: =ROUND(G29/$Q$1*Q29,0) -> 0 | T29: =ROUND(H29/$Q$1*Q29,0) -> 0 | U29: =ROUND(I29/$Q$1*Q29,0) -> 0 | V29: =ROUND(J29/$Q$1*Q29,0) -> 0 | X29: =SUM(R29:V29) -> 0 | AB29: =+SUM(Y29:AA29) -> 0 | AC29: =+X29-AB29+W29 -> 0
B30: 24 | C30: =Salary!C32 -> Rashika Yadav | D30: =Salary!D32 -> 11-07-2025 | E30: Consortium | F30: =+K30*30% -> 0 | G30: =+K30*20% -> 0 | H30: =+K30*20% -> 0 | I30: =+K30*20% -> 0 | J30: =+K30*10% -> 0 | K30: 0 | N30: =+K30+L30+M30 -> 0 | P30: =+O30+N30 -> 0 | Q30: =Salary!Q32 -> 31 | R30: =ROUND(F30/$Q$1*Q30,0) -> 0 | S30: =ROUND(G30/$Q$1*Q30,0) -> 0 | T30: =ROUND(H30/$Q$1*Q30,0) -> 0 | U30: =ROUND(I30/$Q$1*Q30,0) -> 0 | V30: =ROUND(J30/$Q$1*Q30,0) -> 0 | X30: =SUM(R30:V30) -> 0 | AB30: =+SUM(Y30:AA30) -> 0 | AC30: =+X30-AB30+W30 -> 0
B31: 25 | C31: =Salary!C33 -> Aparna Balchandran | D31: =Salary!D33 -> 17-07-2025 | E31: Consortium | F31: =+K31*30% -> 0 | G31: =+K31*20% -> 0 | H31: =+K31*20% -> 0 | I31: =+K31*20% -> 0 | J31: =+K31*10% -> 0 | K31: 0 | N31: =+K31+L31+M31 -> 0 | P31: =+O31+N31 -> 0 | Q31: =Salary!Q33 -> 30 | R31: =ROUND(F31/$Q$1*Q31,0) -> 0 | S31: =ROUND(G31/$Q$1*Q31,0) -> 0 | T31: =ROUND(H31/$Q$1*Q31,0) -> 0 | U31: =ROUND(I31/$Q$1*Q31,0) -> 0 | V31: =ROUND(J31/$Q$1*Q31,0) -> 0 | X31: =SUM(R31:V31) -> 0 | AB31: =+SUM(Y31:AA31) -> 0 | AC31: =+X31-AB31+W31 -> 0
B32: 27 | F32: =+K32*30% -> 0 | G32: =+K32*20% -> 0 | H32: =+K32*20% -> 0 | I32: =+K32*20% -> 0 | J32: =+K32*10% -> 0 | N32: =+K32+L32+M32 -> 0 | P32: =+O32+N32 -> 0 | Q32: =Salary!Q34 -> 31 | R32: =ROUND(F32/$Q$1*Q32,0) -> 0 | S32: =ROUND(G32/$Q$1*Q32,0) -> 0 | T32: =ROUND(H32/$Q$1*Q32,0) -> 0 | U32: =ROUND(I32/$Q$1*Q32,0) -> 0 | V32: =ROUND(J32/$Q$1*Q32,0) -> 0 | X32: =SUM(R32:V32) -> 0 | AB32: =+SUM(Y32:AA32) -> 0 | AC32: =+X32-AB32+W32 -> 0
B33: 28 | F33: =+K33*30% -> 0 | G33: =+K33*20% -> 0 | H33: =+K33*20% -> 0 | I33: =+K33*20% -> 0 | J33: =+K33*10% -> 0 | N33: =+K33+L33+M33 -> 0 | P33: =+O33+N33 -> 0 | Q33: =Salary!Q35 -> 31 | R33: =ROUND(F33/$Q$1*Q33,0) -> 0 | S33: =ROUND(G33/$Q$1*Q33,0) -> 0 | T33: =ROUND(H33/$Q$1*Q33,0) -> 0 | U33: =ROUND(I33/$Q$1*Q33,0) -> 0 | V33: =ROUND(J33/$Q$1*Q33,0) -> 0 | X33: =SUM(R33:V33) -> 0 | AB33: =+SUM(Y33:AA33) -> 0 | AC33: =+X33-AB33+W33 -> 0
B34: 29 | F34: =+K34*30% -> 0 | G34: =+K34*20% -> 0 | H34: =+K34*20% -> 0 | I34: =+K34*20% -> 0 | J34: =+K34*10% -> 0 | N34: =+K34+L34+M34 -> 0 | P34: =+O34+N34 -> 0 | Q34: =Salary!Q36 -> 31 | R34: =ROUND(F34/$Q$1*Q34,0) -> 0 | S34: =ROUND(G34/$Q$1*Q34,0) -> 0 | T34: =ROUND(H34/$Q$1*Q34,0) -> 0 | U34: =ROUND(I34/$Q$1*Q34,0) -> 0 | V34: =ROUND(J34/$Q$1*Q34,0) -> 0 | X34: =SUM(R34:V34) -> 0 | AB34: =+SUM(Y34:AA34) -> 0 | AC34: =+X34-AB34+W34 -> 0
D35: TOTAL | F35: =SUM(F9:F34) -> 26610 | G35: =SUM(G9:G34) -> 17740 | H35: =SUM(H9:H34) -> 17740 | I35: =SUM(I9:I34) -> 17740 | J35: =SUM(J9:J34) -> 8870 | K35: =SUM(K9:K34) -> 88700 | L35: =SUM(L9:L29) -> 0 | M35: =SUM(M9:M29) -> 0 | N35: =SUM(N9:N34) -> 88700 | O35: =SUM(O9:O29) -> 0 | P35: =SUM(P9:P34) -> 88700 | Q35: =SUM(Q9:Q29) -> 581 | R35: =SUM(R9:R29) -> 24608 | S35: =SUM(S9:S29) -> 16406 | T35: =SUM(T9:T29) -> 16406 | U35: =SUM(U9:U29) -> 16406 | V35: =SUM(V9:V29) -> 8202 | W35: =SUM(W9:W29) -> 0 | X35: =SUM(X9:X29) -> 82028 | ... AB35: =SUM(AB9:AB29) -> 0 | AC35: =SUM(AC9:AC34) -> 82028

Sheet Blank

Sheet Annexure
E4: Annexure-I
A6: GROUP : Reinste Nano Ventures Private Limited
A8: NAME OF EMP: | B8: Mr Arun Naithani
A9: Date of Joining | B9: 05.08.2019
A11: EARNING | B11: Amount (Rs.) | D11: DEDUCTION | E11: Amount (Rs.)
A13: BASIC | B13: =+ROUND(B21/2,0) -> 10100 | D13: PF | E13: =ROUND((+B24),0) -> 0
A15: HRA | B15: =B13/2 -> 5050 | D15: ESIC | E15: =+IF(B25>0,ROUNDUP((B21)*0.0175,0),0) -> 0 | F15: =+B13+B17+B19 -> 15150
A17: Statutory Bonus | B17: 1515 | D17: TDS | E17: 0
A19: OTHERS | B19: =B21-B13-B15-B17 -> 3535 | D19: OTHERS | E19: 0
A21: GROSS | B21: 20200 | D21: TOTAL | E21: =+E19+E17+E15+E13 -> 0
A23: RETIRAL BENEFITS | B23: =+B24+B25+B26 -> 486
A24: EMPLOYER PF
A25: EMPLOYER ESIC
A26: Gratuity* | B26: 486
A27: CTC PM | B27: =+B21+B23 -> 20686 | D27: NET PAYABLE PM | E27: =+B21-E21 -> 20200
A29: CTC ANNUAL | B29: =+B27*12 -> 248232 | D29: NET ANNUAL | E29: =+E27*12 -> 242400
A31: * Gratuity amount would be payable only in accordance with the conditions as contained in The Payment of Gratuity Act 1972.
A32: Variable Salary : 20,000 | B32: Target/Achievement
A33: 20000 | B33: =A33*10 -> 200000 | D33: Nil
A34: 20000 | B34: 200001 to 500000 | C34: PM | D34: 0.25 | E34: =+A34*0.25 -> 5000
A35: 20000 | B35: 500001 to 1000000 | C35: PM | D35: 0.5 | E35: =+A35*0.5 -> 10000
A36: 20000 | B36: 1000000 to Above | C36: PM | D36: 1 | E36: =+A36*1 -> 20000
A37: Remarks : Above valid for one year and will be calculated on quarterly basis.
E40: Annexure
A42: GROUP : CONSORTIUM E-LEARNING NETWORK PVT LTD
A44: NAME OF EMP: | B44: Mr. Shipra Gupta
A45: Date of Joining | B45: 01.06.2024
A47: EARNING | B47: Amount (Rs.) | D47: DEDUCTION | E47: Amount (Rs.)
A49: BASIC | B49: =B55/2 -> 7350 | D49: PF | E49: =+B57 -> 1323
A50: HRA | B50: =+B49*50% -> 3675 | D50: ESIC | E50: =+IF(B58>0,ROUNDUP((B55)*0.0075,0),0) -> 111
A51: Coneyance | B51: 1600 | D51: TDS | E51: 0
A52: Statutory Bonus | B52: =+B49*0.09 -> 661.5 | D52: Advance | E52: 0
A53: Special Allowances | B53: =B55-B49-B50-B51-B52 -> 1413.5 | D53: Others | E53: 0
A54: Others | B54: 0 | D54: Professional Tax | E54: 0
A55: Total (A) GROSS | B55: 14700 | D55: Loan EMI | E55: 0
A56: Employer Contribution
A57: EMPLOYER PF | B57: =ROUND((B55-B50)*12%,0) -> 1323
A58: EMPLOYER ESIC | B58: =IF(B54>21000,0,ROUND(B55*0.0325,0)) -> 478
A59: Total (B) | B59: =+B58+B57 -> 1801
A60: Sec-10 Exemp/Perks
...

Sheet Salary Slip
A5: GROUP : CONSORTIUM E-LEARNING NETWORK PVT LTD
A6: PAYSLIP FOR THE MONTH OF : JULY 2024
B7: CONFIDENTIAL
A9: Emp Name | B9: ASAN KUMAR
A10: Total Working Days | B10: 31 | C10: Total Days | D10: 31
A11: Designation: | B11: Manager, IT
A12: EARNING | B12: Amount (Rs.) | D12: DEDUCTION | E12: Amount (Rs.)
A13: BASIC | B13: =B19/2 -> 19144.5 | D13: PF | E13: =+B21 -> 1800
A14: HRA | B14: =+B13*50% -> 9572.25 | D14: ESIC | E14: 0
A15: Coneyance | B15: 1600 | D15: TDS | E15: 0
A16: Statutory Bonus | B16: =+B13*0.09 -> 1723.005 | D16: Advance | E16: 0
A17: Special Allowances | B17: =B19-B13-B14-B15-B16 -> 6249.245 | D17: Others | E17: 0
A18: Others | B18: 0 | D18: Professional Tax | E18: 0
A19: Total (A) GROSS | B19: 38289 | D19: Loan EMI | E19: 0
A20: Employer Contribution
A21: EMPLOYER PF | B21: 1800
A22: EMPLOYER ESIC | B22: =IF(B18>21000,0,ROUND(B18*0.0325,0)) -> 0
A23: Total (B) | B23: =+B22+B21 -> 1800
A24: Sec-10 Exemp/Perks
A25: Health Care | B25: =B31*30% -> 1950
A26: Travelling | B26: =B31*20% -> 1300
A27: Mobile | B27: =B31*20% -> 1300
A28: Internet | B28: =B31*20% -> 1300
A29: Books & Periodicals | B29: =B31*10% -> 650
A30: Others
A31: Total (C) | B31: 6500 | C31: =SUM(B25:B30)-B31 -> 0 | D31: Total Dedu. | E31: =SUM(E13:E30) -> 1800
A32: Total (A+B+C) | B32: =B19+B23+B31 -> 46589 | D32: NET PAYABLE | E32: =+B19-E19 -> 38289
A40: GROUP : CONSORTIUM E-LEARNING NETWORK PVT LTD
A41: PAYSLIP FOR THE MONTH OF : NOVEMBER 2024
B42: CONFIDENTIAL
A44: Emp Name | B44: Manish Singh
A45: Total Working Days | B45: 25.5 | C45: Total Days | D45: 30
A46: Designation: | B46: Associate Editor
A47: EARNING | B47: Amount (Rs.) | D47: DEDUCTION | E47: Amount (Rs.)
A48: BASIC | B48: =B54/2 -> 9077 | D48: PF | E48: =+B56 -> 1634
A49: HRA | B49: =+B48*50% -> 4538.5 | D49: ESIC | E49: 0
A50: Coneyance | B50: 1600 | D50: TDS | E50: 0
A51: Statutory Bonus | B51: =+B48*0.09 -> 816.93 | D51: Advance | E51: 0
A52: Special Allowances | B52: =B54-B48-B49-B50-B51 -> 2121.57 | D52: Others | E52: 0
A53: Others | B53: 0 | D53: Professional Tax | E53: 0
...

Sheet Subham Gautam
B6: GROUP : CONSORTIUM E-LEARNING NETWORK PVT LTD
B7: PAYSLIP FOR THE MONTH OF : MARCH 2025
C8: CONFIDENTIAL
B10: Emp Name | C10: Subham Gautam | D10: Month | E10: March 2025
B11: Total Working Days | C11: 25.5 | D11: Total Days | E11: 31
B12: Designation: | C12: Web Developer
B13: EARNING | C13: Amount (Rs.) | E13: DEDUCTION | F13: Amount (Rs.)
B14: BASIC | C14: 7328 | E14: PF | F14: 1319
B15: HRA | C15: 3665 | E15: ESIC | F15: 110
B16: Coneyance | C16: 1316 | E16: TDS | F16: 0
B17: Statutory Bonus | C17: 660 | E17: Advance | F17: 0
B18: Special Allowances | C18: 1688 | E18: Others | F18: 0
B19: Others | C19: 0 | E19: Professional Tax | F19: 0
B20: Total (A) GROSS | C20: =SUM(C14:C19) -> 14657 | E20: Loan EMI | F20: 0
B21: Employer Contribution
B22: EMPLOYER PF | C22: 1800
B23: EMPLOYER ESIC | C23: =IF(C19>21000,0,ROUND(C19*0.0325,0)) -> 0
B24: Total (B) | C24: =+C23+C22 -> 1800
B25: Sec-10 Exemp/Perks
B26: Health Care | C26: =C32*30% -> 592.2
B27: Travelling | C27: =C32*20% -> 394.8
B28: Mobile | C28: =C32*20% -> 394.8
B29: Internet | C29: =C32*20% -> 394.8
B30: Books & Periodicals | C30: =C32*10% -> 197.4
B31: Others
B32: Total (C) | C32: 1974 | D32: =SUM(C26:C31)-C32 -> 0 | E32: Total Dedu. | F32: =SUM(F14:F31) -> 1429
B33: Total (A+B+C) | C33: =C20+C24+C32 -> 18431 | E33: NET PAYABLE | F33: =C33-C24-F32 -> 15202
B40: For Consortium e-Learning Network Private Limited
B45: (PUNEET MEHROTRA)
B46: MANAGING DIRECTOR
B67: GROUP : CONSORTIUM E-LEARNING NETWORK PVT LTD
B68: PAYSLIP FOR THE MONTH OF : FEBRUARY 2025
C69: CONFIDENTIAL
B71: Emp Name | C71: Subham Gautam | D71: Month | E71: February 2025
B72: Total Working Days | C72: 22.5 | D72: Total Days | E72: 28
B73: Designation: | C73: Web Developer
B74: EARNING | C74: Amount (Rs.) | E74: DEDUCTION | F74: Amount (Rs.)
B75: BASIC | C75: 7159 | E75: PF | F75: 1289 | G75: basic +hra@12%
B76: HRA | C76: 3580 | E76: ESIC | F76: 108 | G76: Gross*0.75%
B77: Coneyance | C77: 1286 | E77: TDS | F77: 0
...

Sheet Salary Monthwise
A1: SALARY DETAILS COMPANYWSE FOR THE YEAR 2024-25
A3: Month | B3: Reinste | C3: Celnet | D3: Dhruv | E3: IT Break | F3: TOTAL (Rs.)
A4: April 24 | B4: =88774 -> 88774 | C4: =1204274+169601 -> 1373875 | D4: =135368+71000 -> 206368 | E4: =115076+74000 -> 189076 | F4: =SUM(B4:E4) -> 1858093
A5: May 24 | B5: =88774+10000 -> 98774 | C5: =1172715+166800+211000 -> 1550515 | D5: =157598+81100+19000 -> 257698 | E5: =121375+92500+12500 -> 226375 | F5: =SUM(B5:E5) -> 2133362
A6: June 24 | B6: =88774+10000 -> 98774 | C6: =1200734+158300+226210 -> 1585244 | D6: =157598+83100+12710 -> 253408 | E6: =102375+92500+6500 -> 201375 | F6: =SUM(B6:E6) -> 2138801
A7: July 24 | B7: =88774+10000 -> 98774 | C7: =1243277+148117+246210 -> 1637604 | D7: =138598+12710 -> 151308 | E7: =108375+95500+6500 -> 210375 | F7: =SUM(B7:E7) -> 2098061
A8: Aug 24 | B8: =88774+10000 -> 98774 | C8: =1213799+151100+273810 -> 1638709 | D8: =138598+13000 -> 151598 | E8: =108375+56500+13000 -> 177875 | F8: =SUM(B8:E8) -> 2066956
A9: Sept 24 | B9: =88774+10000 -> 98774 | C9: =1133472+160400+301510 -> 1595382 | D9: =105598+9750 -> 115348 | E9: =130375+68500+6500 -> 205375 | F9: =SUM(B9:E9) -> 2014879
A10: Oct 24 | B10: =88774+10000 -> 98774 | C10: =1185516+147918+248052 -> 1581486 | D10: =130958+10000 -> 140958 | E10: =145375+6500 -> 151875 | F10: =SUM(B10:E10) -> 1973093
A11: Nov 24 | B11: =88774+10000 -> 98774 | C11: =1162016+147000+286310 -> 1595326 | D11: =130598+10000 -> 140598 | E11: =133375+6500 -> 139875 | F11: =SUM(B11:E11) -> 1974573
A12: Dec 24 | B12: =88774+10000 -> 98774 | C12: =1094066+141000+315052 -> 1550118 | D12: =144828+10000 -> 154828 | E12: =133375+6500 -> 139875 | F12: =SUM(B12:E12) -> 1943595
A13: Jan 25 | B13: =88774+10000 -> 98774 | C13: =1094066+154000+285714 -> 1533780 | D13: =132328+10000 -> 142328 | E13: =133375+6500 -> 139875 | F13: =SUM(B13:E13) -> 1914757
A14: Feb 25 | F14: =SUM(B14:E14) -> 0
A15: Mar 25 | F15: =SUM(B15:E15) -> 0
F16: =SUM(B16:E16) -> 0
A17: TOTAL | B17: =SUM(B4:B16) -> 977740 | C17: =SUM(C4:C16) -> 15642039 | D17: =SUM(D4:D16) -> 1714440 | E17: =SUM(E4:E16) -> 1781951 | F17: =SUM(F4:F16) -> 20116170
B18: Inclusive PF & ESIC

Sheet Attendance Sheet
B1: ATTENDANCE SHEET : __________________
A3: S.No. | B3: Name of Employee | C3: Time in | D3: Signature | E3: Time Out | F3: Signature
A4: 1 | B4: Mamchand Singh
A5: =A4+1 -> 2 | B5: Gulab
A6: =A5+1 -> 3 | B6: Sanjeev Singh
A7: =A6+1 -> 4 | B7: Asan Kumar
A8: =A7+1 -> 5 | B8: Ashwani Kumar
A9: =A8+1 -> 6 | B9: Quaisher Hossain
A10: =A9+1 -> 7 | B10: Manish Harishankar
A11: =A10+1 -> 8 | B11: Gagan Kumar
A12: =A11+1 -> 9 | B12: Ravi Kumar
A13: =A12+1 -> 10 | B13: Amit Kumar Rai
A14: =A13+1 -> 11 | B14: Aarti Sharma
A15: =A14+1 -> 12 | B15: Monika Tiwari
A16: =A15+1 -> 13 | B16: Divya Dengry
... A45: =A44+1 -> 42 | B45: Parul Jaiswal
A46: =A45+1 -> 43
A47: =A46+1 -> 44
A48: =A47+1 -> 45

Sheet SALARY NEW SLIP
A2: GROUP : REINSTE NANO VENTURES PVT LTD
A3: SALARY PAYSLIP FOR THE MONTH OF : JANUARY 2025
B4: CONFIDENTIAL
A6: Emp Name | B6: MAMCHAND SINGH
A7: Total Working Days | B7: 31 | C7: Total Days | D7: 31
A8: Designation: | B8: Manager Operations
A9: EARNING | B9: Amount (Rs.) | C9: DEDUCTION | E9: Amount (Rs.)
A10: BASIC | B10: 20150.5 | D10: PF | E10: =+B18 -> 1800
A11: HRA | B11: =+B10*50% -> 10075.25 | D11: ESIC | E11: 0
A12: Conveyance | B12: 1600 | D12: TDS | E12: 0
A13: Statutory Bonus | B13: =+B10*0.09 -> 1813.545 | D13: Advance | E13: 0
A14: Special Allowances | B14: =B16-B10-B11-B12-B13 -> 6661.705 | D14: Others | E14: 0
A15: Others | B15: 0 | D15: Professional Tax | E15: 0
A16: Total (A) GROSS | B16: 40301 | D16: Loan EMI | E16: 0
A17: Employer Contribution
A18: EMPLOYER PF | B18: 1800
A19: EMPLOYER ESIC | B19: =IF(B15>21000,0,ROUND(B15*0.0325,0)) -> 0
A20: Total (B) | B20: =+B19+B18 -> 1800
D21: Total Dedu. | E21: =SUM(E10:E20) -> 1800
A22: Total (A+B) | B22: =B16+B20 -> 42101 | D22: NET PAYABLE | E22: =B22-E21 -> 40301
A25: REIMBURSEMENT CLAIM (January 2025)
A26: Health Care | B26: 1200
A27: Travelling | B27: 800
A28: Mobile | B28: 800
A29: Internet | B29: 800
A30: Books & Periodicals | B30: 400
A31: Others
A32: Total | B32: 4000
